2025-10-05 01:06:22,364 ERROR: Exception on / [GET] [in /Users/jeremybullis/Desktop/F1DataProject/venv/lib/python3.11/site-packages/flask/app.py:875]
Traceback (most recent call last):
  File "/Users/jeremybullis/Desktop/F1DataProject/venv/lib/python3.11/site-packages/flask/app.py", line 1511, in wsgi_app
    response = self.full_dispatch_request()
               ^^^^^^^^^^^^^^^^^^^^^^^^^^^^
  File "/Users/jeremybullis/Desktop/F1DataProject/venv/lib/python3.11/site-packages/flask/app.py", line 919, in full_dispatch_request
    rv = self.handle_user_exception(e)
         ^^^^^^^^^^^^^^^^^^^^^^^^^^^^^
  File "/Users/jeremybullis/Desktop/F1DataProject/venv/lib/python3.11/site-packages/flask/app.py", line 917, in full_dispatch_request
    rv = self.dispatch_request()
         ^^^^^^^^^^^^^^^^^^^^^^^
  File "/Users/jeremybullis/Desktop/F1DataProject/venv/lib/python3.11/site-packages/flask/app.py", line 902, in dispatch_request
    return self.ensure_sync(self.view_functions[rule.endpoint])(**view_args)  # type: ignore[no-any-return]
           ^^^^^^^^^^^^^^^^^^^^^^^^^^^^^^^^^^^^^^^^^^^^^^^^^^^^^^^^^^^^^^^^^
  File "/Users/jeremybullis/Desktop/F1DataProject/app/routes.py", line 59, in index
    circuit_map.generate_circuit_map(location[0], location[1])
  File "/Users/jeremybullis/Desktop/F1DataProject/util/circuit_map.py", line 18, in generate_circuit_map
    fig.update_geos(
  File "/Users/jeremybullis/Desktop/F1DataProject/venv/lib/python3.11/site-packages/plotly/graph_objs/_figure.py", line 21721, in update_geos
    obj.update(patch, overwrite=overwrite, **kwargs)
  File "/Users/jeremybullis/Desktop/F1DataProject/venv/lib/python3.11/site-packages/plotly/basedatatypes.py", line 5195, in update
    BaseFigure._perform_update(self, kwargs, overwrite=overwrite)
  File "/Users/jeremybullis/Desktop/F1DataProject/venv/lib/python3.11/site-packages/plotly/basedatatypes.py", line 3971, in _perform_update
    BaseFigure._perform_update(plotly_obj[key], val)
  File "/Users/jeremybullis/Desktop/F1DataProject/venv/lib/python3.11/site-packages/plotly/basedatatypes.py", line 3992, in _perform_update
    plotly_obj[key] = val
    ~~~~~~~~~~^^^^^
  File "/Users/jeremybullis/Desktop/F1DataProject/venv/lib/python3.11/site-packages/plotly/basedatatypes.py", line 4932, in __setitem__
    self._set_prop(prop, value)
  File "/Users/jeremybullis/Desktop/F1DataProject/venv/lib/python3.11/site-packages/plotly/basedatatypes.py", line 5276, in _set_prop
    raise err
  File "/Users/jeremybullis/Desktop/F1DataProject/venv/lib/python3.11/site-packages/plotly/basedatatypes.py", line 5271, in _set_prop
    val = validator.validate_coerce(val)
          ^^^^^^^^^^^^^^^^^^^^^^^^^^^^^^
  File "/Users/jeremybullis/Desktop/F1DataProject/venv/lib/python3.11/site-packages/_plotly_utils/basevalidators.py", line 792, in validate_coerce
    self.raise_invalid_val(v)
  File "/Users/jeremybullis/Desktop/F1DataProject/venv/lib/python3.11/site-packages/_plotly_utils/basevalidators.py", line 298, in raise_invalid_val
    raise ValueError(
ValueError: 
    Invalid value of type 'builtins.str' received for the 'lat' property of layout.geo.projection.rotation
        Received value: '40.3725'

    The 'lat' property is a number and may be specified as:
      - An int or float
2025-10-05 01:07:07,988 INFO: Microblog startup [in /Users/jeremybullis/Desktop/F1DataProject/app/__init__.py:30]
2025-10-05 01:07:12,345 ERROR: Exception on / [GET] [in /Users/jeremybullis/Desktop/F1DataProject/venv/lib/python3.11/site-packages/flask/app.py:875]
Traceback (most recent call last):
  File "/Users/jeremybullis/Desktop/F1DataProject/venv/lib/python3.11/site-packages/flask/app.py", line 1511, in wsgi_app
    response = self.full_dispatch_request()
               ^^^^^^^^^^^^^^^^^^^^^^^^^^^^
  File "/Users/jeremybullis/Desktop/F1DataProject/venv/lib/python3.11/site-packages/flask/app.py", line 919, in full_dispatch_request
    rv = self.handle_user_exception(e)
         ^^^^^^^^^^^^^^^^^^^^^^^^^^^^^
  File "/Users/jeremybullis/Desktop/F1DataProject/venv/lib/python3.11/site-packages/flask/app.py", line 917, in full_dispatch_request
    rv = self.dispatch_request()
         ^^^^^^^^^^^^^^^^^^^^^^^
  File "/Users/jeremybullis/Desktop/F1DataProject/venv/lib/python3.11/site-packages/flask/app.py", line 902, in dispatch_request
    return self.ensure_sync(self.view_functions[rule.endpoint])(**view_args)  # type: ignore[no-any-return]
           ^^^^^^^^^^^^^^^^^^^^^^^^^^^^^^^^^^^^^^^^^^^^^^^^^^^^^^^^^^^^^^^^^
  File "/Users/jeremybullis/Desktop/F1DataProject/app/routes.py", line 59, in index
    circuit_map.generate_circuit_map(location[0], location[1])
  File "/Users/jeremybullis/Desktop/F1DataProject/util/circuit_map.py", line 28, in generate_circuit_map
    fig.write_image("static/media/maps/map.png")
  File "/Users/jeremybullis/Desktop/F1DataProject/venv/lib/python3.11/site-packages/plotly/basedatatypes.py", line 3895, in write_image
    return pio.write_image(self, *args, **kwargs)
           ^^^^^^^^^^^^^^^^^^^^^^^^^^^^^^^^^^^^^^
  File "/Users/jeremybullis/Desktop/F1DataProject/venv/lib/python3.11/site-packages/plotly/io/_kaleido.py", line 528, in write_image
    img_data = to_image(
               ^^^^^^^^^
  File "/Users/jeremybullis/Desktop/F1DataProject/venv/lib/python3.11/site-packages/plotly/io/_kaleido.py", line 345, in to_image
    raise ValueError(
ValueError: 
Image export using the "kaleido" engine requires the Kaleido package,
which can be installed using pip:

    $ pip install --upgrade kaleido

2025-10-05 01:08:15,697 INFO: Microblog startup [in /Users/jeremybullis/Desktop/F1DataProject/app/__init__.py:30]
2025-10-05 01:08:34,200 ERROR: Exception on / [GET] [in /Users/jeremybullis/Desktop/F1DataProject/venv/lib/python3.11/site-packages/flask/app.py:875]
Traceback (most recent call last):
  File "/Users/jeremybullis/Desktop/F1DataProject/venv/lib/python3.11/site-packages/flask/app.py", line 1511, in wsgi_app
    response = self.full_dispatch_request()
               ^^^^^^^^^^^^^^^^^^^^^^^^^^^^
  File "/Users/jeremybullis/Desktop/F1DataProject/venv/lib/python3.11/site-packages/flask/app.py", line 919, in full_dispatch_request
    rv = self.handle_user_exception(e)
         ^^^^^^^^^^^^^^^^^^^^^^^^^^^^^
  File "/Users/jeremybullis/Desktop/F1DataProject/venv/lib/python3.11/site-packages/flask/app.py", line 917, in full_dispatch_request
    rv = self.dispatch_request()
         ^^^^^^^^^^^^^^^^^^^^^^^
  File "/Users/jeremybullis/Desktop/F1DataProject/venv/lib/python3.11/site-packages/flask/app.py", line 902, in dispatch_request
    return self.ensure_sync(self.view_functions[rule.endpoint])(**view_args)  # type: ignore[no-any-return]
           ^^^^^^^^^^^^^^^^^^^^^^^^^^^^^^^^^^^^^^^^^^^^^^^^^^^^^^^^^^^^^^^^^
  File "/Users/jeremybullis/Desktop/F1DataProject/app/routes.py", line 59, in index
    circuit_map.generate_circuit_map(location[0], location[1])
  File "/Users/jeremybullis/Desktop/F1DataProject/util/circuit_map.py", line 28, in generate_circuit_map
    fig.write_image("static/media/maps/map.png")
  File "/Users/jeremybullis/Desktop/F1DataProject/venv/lib/python3.11/site-packages/plotly/basedatatypes.py", line 3895, in write_image
    return pio.write_image(self, *args, **kwargs)
           ^^^^^^^^^^^^^^^^^^^^^^^^^^^^^^^^^^^^^^
  File "/Users/jeremybullis/Desktop/F1DataProject/venv/lib/python3.11/site-packages/plotly/io/_kaleido.py", line 555, in write_image
    path.write_bytes(img_data)
  File "/Library/Frameworks/Python.framework/Versions/3.11/lib/python3.11/pathlib.py", line 1067, in write_bytes
    with self.open(mode='wb') as f:
         ^^^^^^^^^^^^^^^^^^^^
  File "/Library/Frameworks/Python.framework/Versions/3.11/lib/python3.11/pathlib.py", line 1044, in open
    return io.open(self, mode, buffering, encoding, errors, newline)
           ^^^^^^^^^^^^^^^^^^^^^^^^^^^^^^^^^^^^^^^^^^^^^^^^^^^^^^^^^
FileNotFoundError: [Errno 2] No such file or directory: 'static/media/maps/map.png'
2025-10-05 01:09:11,171 INFO: Microblog startup [in /Users/jeremybullis/Desktop/F1DataProject/app/__init__.py:30]
