2025-10-05 01:09:17,512 ERROR: Exception on / [GET] [in /Users/jeremybullis/Desktop/F1DataProject/venv/lib/python3.11/site-packages/flask/app.py:875]
Traceback (most recent call last):
  File "/Users/jeremybullis/Desktop/F1DataProject/venv/lib/python3.11/site-packages/flask/app.py", line 1511, in wsgi_app
    response = self.full_dispatch_request()
               ^^^^^^^^^^^^^^^^^^^^^^^^^^^^
  File "/Users/jeremybullis/Desktop/F1DataProject/venv/lib/python3.11/site-packages/flask/app.py", line 919, in full_dispatch_request
    rv = self.handle_user_exception(e)
         ^^^^^^^^^^^^^^^^^^^^^^^^^^^^^
  File "/Users/jeremybullis/Desktop/F1DataProject/venv/lib/python3.11/site-packages/flask/app.py", line 917, in full_dispatch_request
    rv = self.dispatch_request()
         ^^^^^^^^^^^^^^^^^^^^^^^
  File "/Users/jeremybullis/Desktop/F1DataProject/venv/lib/python3.11/site-packages/flask/app.py", line 902, in dispatch_request
    return self.ensure_sync(self.view_functions[rule.endpoint])(**view_args)  # type: ignore[no-any-return]
           ^^^^^^^^^^^^^^^^^^^^^^^^^^^^^^^^^^^^^^^^^^^^^^^^^^^^^^^^^^^^^^^^^
  File "/Users/jeremybullis/Desktop/F1DataProject/app/routes.py", line 59, in index
    circuit_map.generate_circuit_map(location[0], location[1])
  File "/Users/jeremybullis/Desktop/F1DataProject/util/circuit_map.py", line 28, in generate_circuit_map
    fig.write_image("/static/media/maps/map.png")
  File "/Users/jeremybullis/Desktop/F1DataProject/venv/lib/python3.11/site-packages/plotly/basedatatypes.py", line 3895, in write_image
    return pio.write_image(self, *args, **kwargs)
           ^^^^^^^^^^^^^^^^^^^^^^^^^^^^^^^^^^^^^^
  File "/Users/jeremybullis/Desktop/F1DataProject/venv/lib/python3.11/site-packages/plotly/io/_kaleido.py", line 555, in write_image
    path.write_bytes(img_data)
  File "/Library/Frameworks/Python.framework/Versions/3.11/lib/python3.11/pathlib.py", line 1067, in write_bytes
    with self.open(mode='wb') as f:
         ^^^^^^^^^^^^^^^^^^^^
  File "/Library/Frameworks/Python.framework/Versions/3.11/lib/python3.11/pathlib.py", line 1044, in open
    return io.open(self, mode, buffering, encoding, errors, newline)
           ^^^^^^^^^^^^^^^^^^^^^^^^^^^^^^^^^^^^^^^^^^^^^^^^^^^^^^^^^
FileNotFoundError: [Errno 2] No such file or directory: '/static/media/maps/map.png'
2025-10-05 01:09:37,034 INFO: Microblog startup [in /Users/jeremybullis/Desktop/F1DataProject/app/__init__.py:30]
2025-10-05 01:09:44,136 ERROR: Exception on / [GET] [in /Users/jeremybullis/Desktop/F1DataProject/venv/lib/python3.11/site-packages/flask/app.py:875]
Traceback (most recent call last):
  File "/Users/jeremybullis/Desktop/F1DataProject/venv/lib/python3.11/site-packages/flask/app.py", line 1511, in wsgi_app
    response = self.full_dispatch_request()
               ^^^^^^^^^^^^^^^^^^^^^^^^^^^^
  File "/Users/jeremybullis/Desktop/F1DataProject/venv/lib/python3.11/site-packages/flask/app.py", line 919, in full_dispatch_request
    rv = self.handle_user_exception(e)
         ^^^^^^^^^^^^^^^^^^^^^^^^^^^^^
  File "/Users/jeremybullis/Desktop/F1DataProject/venv/lib/python3.11/site-packages/flask/app.py", line 917, in full_dispatch_request
    rv = self.dispatch_request()
         ^^^^^^^^^^^^^^^^^^^^^^^
  File "/Users/jeremybullis/Desktop/F1DataProject/venv/lib/python3.11/site-packages/flask/app.py", line 902, in dispatch_request
    return self.ensure_sync(self.view_functions[rule.endpoint])(**view_args)  # type: ignore[no-any-return]
           ^^^^^^^^^^^^^^^^^^^^^^^^^^^^^^^^^^^^^^^^^^^^^^^^^^^^^^^^^^^^^^^^^
  File "/Users/jeremybullis/Desktop/F1DataProject/app/routes.py", line 59, in index
    circuit_map.generate_circuit_map(location[0], location[1])
  File "/Users/jeremybullis/Desktop/F1DataProject/util/circuit_map.py", line 28, in generate_circuit_map
    fig.write_image("/app/static/media/maps/map.png")
  File "/Users/jeremybullis/Desktop/F1DataProject/venv/lib/python3.11/site-packages/plotly/basedatatypes.py", line 3895, in write_image
    return pio.write_image(self, *args, **kwargs)
           ^^^^^^^^^^^^^^^^^^^^^^^^^^^^^^^^^^^^^^
  File "/Users/jeremybullis/Desktop/F1DataProject/venv/lib/python3.11/site-packages/plotly/io/_kaleido.py", line 555, in write_image
    path.write_bytes(img_data)
  File "/Library/Frameworks/Python.framework/Versions/3.11/lib/python3.11/pathlib.py", line 1067, in write_bytes
    with self.open(mode='wb') as f:
         ^^^^^^^^^^^^^^^^^^^^
  File "/Library/Frameworks/Python.framework/Versions/3.11/lib/python3.11/pathlib.py", line 1044, in open
    return io.open(self, mode, buffering, encoding, errors, newline)
           ^^^^^^^^^^^^^^^^^^^^^^^^^^^^^^^^^^^^^^^^^^^^^^^^^^^^^^^^^
FileNotFoundError: [Errno 2] No such file or directory: '/app/static/media/maps/map.png'
2025-10-05 01:11:07,278 INFO: Microblog startup [in /Users/jeremybullis/Desktop/F1DataProject/app/__init__.py:30]
2025-10-05 01:11:57,858 INFO: Microblog startup [in /Users/jeremybullis/Desktop/F1DataProject/app/__init__.py:30]
2025-10-05 01:15:30,954 INFO: Microblog startup [in /Users/jeremybullis/Desktop/F1DataProject/app/__init__.py:30]
2025-10-05 01:15:36,616 ERROR: Exception on / [GET] [in /Users/jeremybullis/Desktop/F1DataProject/venv/lib/python3.11/site-packages/flask/app.py:875]
Traceback (most recent call last):
  File "/Users/jeremybullis/Desktop/F1DataProject/venv/lib/python3.11/site-packages/flask/app.py", line 1511, in wsgi_app
    response = self.full_dispatch_request()
               ^^^^^^^^^^^^^^^^^^^^^^^^^^^^
  File "/Users/jeremybullis/Desktop/F1DataProject/venv/lib/python3.11/site-packages/flask/app.py", line 919, in full_dispatch_request
    rv = self.handle_user_exception(e)
         ^^^^^^^^^^^^^^^^^^^^^^^^^^^^^
  File "/Users/jeremybullis/Desktop/F1DataProject/venv/lib/python3.11/site-packages/flask/app.py", line 917, in full_dispatch_request
    rv = self.dispatch_request()
         ^^^^^^^^^^^^^^^^^^^^^^^
  File "/Users/jeremybullis/Desktop/F1DataProject/venv/lib/python3.11/site-packages/flask/app.py", line 902, in dispatch_request
    return self.ensure_sync(self.view_functions[rule.endpoint])(**view_args)  # type: ignore[no-any-return]
           ^^^^^^^^^^^^^^^^^^^^^^^^^^^^^^^^^^^^^^^^^^^^^^^^^^^^^^^^^^^^^^^^^
  File "/Users/jeremybullis/Desktop/F1DataProject/app/routes.py", line 59, in index
    circuit_map.generate_circuit_map(location[0], location[1])
TypeError: generate_circuit_map() missing 1 required positional argument: 'circuit_name'
2025-10-05 01:15:58,385 INFO: Microblog startup [in /Users/jeremybullis/Desktop/F1DataProject/app/__init__.py:30]
2025-10-05 01:16:27,524 INFO: Microblog startup [in /Users/jeremybullis/Desktop/F1DataProject/app/__init__.py:30]
2025-10-05 01:17:00,604 INFO: Microblog startup [in /Users/jeremybullis/Desktop/F1DataProject/app/__init__.py:30]
2025-10-05 01:18:12,404 INFO: Microblog startup [in /Users/jeremybullis/Desktop/F1DataProject/app/__init__.py:30]
2025-10-05 01:18:49,143 INFO: Microblog startup [in /Users/jeremybullis/Desktop/F1DataProject/app/__init__.py:30]
2025-10-05 01:19:09,802 INFO: Microblog startup [in /Users/jeremybullis/Desktop/F1DataProject/app/__init__.py:30]
2025-10-05 01:20:00,817 INFO: Microblog startup [in /Users/jeremybullis/Desktop/F1DataProject/app/__init__.py:30]
2025-10-05 01:20:35,263 INFO: Microblog startup [in /Users/jeremybullis/Desktop/F1DataProject/app/__init__.py:30]
2025-10-05 01:21:08,569 INFO: Microblog startup [in /Users/jeremybullis/Desktop/F1DataProject/app/__init__.py:30]
2025-10-05 01:22:47,898 INFO: Microblog startup [in /Users/jeremybullis/Desktop/F1DataProject/app/__init__.py:30]
2025-10-05 01:24:04,506 INFO: Microblog startup [in /Users/jeremybullis/Desktop/F1DataProject/app/__init__.py:30]
2025-10-05 01:25:03,821 INFO: Microblog startup [in /Users/jeremybullis/Desktop/F1DataProject/app/__init__.py:30]
2025-10-05 01:25:29,713 INFO: Microblog startup [in /Users/jeremybullis/Desktop/F1DataProject/app/__init__.py:30]
2025-10-05 01:26:48,776 INFO: Microblog startup [in /Users/jeremybullis/Desktop/F1DataProject/app/__init__.py:30]
2025-10-05 01:27:26,685 INFO: Microblog startup [in /Users/jeremybullis/Desktop/F1DataProject/app/__init__.py:30]
2025-10-05 01:27:59,005 INFO: Microblog startup [in /Users/jeremybullis/Desktop/F1DataProject/app/__init__.py:30]
2025-10-05 01:28:33,145 INFO: Microblog startup [in /Users/jeremybullis/Desktop/F1DataProject/app/__init__.py:30]
2025-10-05 01:34:00,164 INFO: Microblog startup [in /Users/jeremybullis/Desktop/F1DataProject/app/__init__.py:30]
2025-10-05 01:35:39,981 INFO: Microblog startup [in /Users/jeremybullis/Desktop/F1DataProject/app/__init__.py:30]
2025-10-05 01:35:58,373 INFO: Microblog startup [in /Users/jeremybullis/Desktop/F1DataProject/app/__init__.py:30]
2025-10-05 01:37:05,909 INFO: Microblog startup [in /Users/jeremybullis/Desktop/F1DataProject/app/__init__.py:30]
2025-10-05 01:37:43,569 INFO: Microblog startup [in /Users/jeremybullis/Desktop/F1DataProject/app/__init__.py:30]
2025-10-05 01:38:12,620 INFO: Microblog startup [in /Users/jeremybullis/Desktop/F1DataProject/app/__init__.py:30]
